2016-03-08 02:50:58,372 INFO:             errors [in app.py:64]
2016-03-08 02:51:10,004 ERROR:             Exception on /ocr/ [POST] [in /Users/varunshah1106/Documents/ocr-test/env/lib/python2.7/site-packages/flask/app.py:1423]
Traceback (most recent call last):
  File "/Users/varunshah1106/Documents/ocr-test/env/lib/python2.7/site-packages/flask/app.py", line 1817, in wsgi_app
    response = self.full_dispatch_request()
  File "/Users/varunshah1106/Documents/ocr-test/env/lib/python2.7/site-packages/flask/app.py", line 1477, in full_dispatch_request
    rv = self.handle_user_exception(e)
  File "/Users/varunshah1106/Documents/ocr-test/env/lib/python2.7/site-packages/flask/app.py", line 1381, in handle_user_exception
    reraise(exc_type, exc_value, tb)
  File "/Users/varunshah1106/Documents/ocr-test/env/lib/python2.7/site-packages/flask/app.py", line 1475, in full_dispatch_request
    rv = self.dispatch_request()
  File "/Users/varunshah1106/Documents/ocr-test/env/lib/python2.7/site-packages/flask/app.py", line 1461, in dispatch_request
    return self.view_functions[rule.endpoint](**req.view_args)
  File "app.py", line 30, in ocr
    print response['textAnnotations'][0]['description']
TypeError: 'NoneType' object has no attribute '__getitem__'
2016-03-08 03:03:17,878 INFO:             errors [in app.py:64]
2016-03-08 03:03:29,351 ERROR:             Exception on /ocr/ [POST] [in /Users/varunshah1106/Documents/ocr-test/env/lib/python2.7/site-packages/flask/app.py:1423]
Traceback (most recent call last):
  File "/Users/varunshah1106/Documents/ocr-test/env/lib/python2.7/site-packages/flask/app.py", line 1817, in wsgi_app
    response = self.full_dispatch_request()
  File "/Users/varunshah1106/Documents/ocr-test/env/lib/python2.7/site-packages/flask/app.py", line 1477, in full_dispatch_request
    rv = self.handle_user_exception(e)
  File "/Users/varunshah1106/Documents/ocr-test/env/lib/python2.7/site-packages/flask/app.py", line 1381, in handle_user_exception
    reraise(exc_type, exc_value, tb)
  File "/Users/varunshah1106/Documents/ocr-test/env/lib/python2.7/site-packages/flask/app.py", line 1475, in full_dispatch_request
    rv = self.dispatch_request()
  File "/Users/varunshah1106/Documents/ocr-test/env/lib/python2.7/site-packages/flask/app.py", line 1461, in dispatch_request
    return self.view_functions[rule.endpoint](**req.view_args)
  File "app.py", line 29, in ocr
    response = VisionApi().ocr(image.read())
  File "/Users/varunshah1106/Documents/ocr-test/flask_server/ocr.py", line 67, in ocr
    media_body = MediaFileUpload('temp.jpg', resumable=True, ocr=True)
  File "/Users/varunshah1106/Documents/ocr-test/env/lib/python2.7/site-packages/oauth2client/util.py", line 137, in positional_wrapper
    return wrapped(*args, **kwargs)
TypeError: __init__() got an unexpected keyword argument 'ocr'
2016-03-08 03:04:01,661 INFO:             errors [in app.py:64]
2016-03-08 03:04:05,754 ERROR:             Exception on /ocr/ [POST] [in /Users/varunshah1106/Documents/ocr-test/env/lib/python2.7/site-packages/flask/app.py:1423]
Traceback (most recent call last):
  File "/Users/varunshah1106/Documents/ocr-test/env/lib/python2.7/site-packages/flask/app.py", line 1817, in wsgi_app
    response = self.full_dispatch_request()
  File "/Users/varunshah1106/Documents/ocr-test/env/lib/python2.7/site-packages/flask/app.py", line 1477, in full_dispatch_request
    rv = self.handle_user_exception(e)
  File "/Users/varunshah1106/Documents/ocr-test/env/lib/python2.7/site-packages/flask/app.py", line 1381, in handle_user_exception
    reraise(exc_type, exc_value, tb)
  File "/Users/varunshah1106/Documents/ocr-test/env/lib/python2.7/site-packages/flask/app.py", line 1475, in full_dispatch_request
    rv = self.dispatch_request()
  File "/Users/varunshah1106/Documents/ocr-test/env/lib/python2.7/site-packages/flask/app.py", line 1461, in dispatch_request
    return self.view_functions[rule.endpoint](**req.view_args)
  File "app.py", line 29, in ocr
    response = VisionApi().ocr(image.read())
  File "/Users/varunshah1106/Documents/ocr-test/flask_server/ocr.py", line 66, in ocr
    media_body = MediaFileUpload('temp.jpg', resumable=True, ocr=True)
  File "/Users/varunshah1106/Documents/ocr-test/env/lib/python2.7/site-packages/oauth2client/util.py", line 137, in positional_wrapper
    return wrapped(*args, **kwargs)
TypeError: __init__() got an unexpected keyword argument 'ocr'
2016-03-08 03:06:59,054 INFO:             errors [in app.py:64]
2016-03-08 03:07:07,567 ERROR:             Exception on /ocr/ [POST] [in /Users/varunshah1106/Documents/ocr-test/env/lib/python2.7/site-packages/flask/app.py:1423]
Traceback (most recent call last):
  File "/Users/varunshah1106/Documents/ocr-test/env/lib/python2.7/site-packages/flask/app.py", line 1817, in wsgi_app
    response = self.full_dispatch_request()
  File "/Users/varunshah1106/Documents/ocr-test/env/lib/python2.7/site-packages/flask/app.py", line 1477, in full_dispatch_request
    rv = self.handle_user_exception(e)
  File "/Users/varunshah1106/Documents/ocr-test/env/lib/python2.7/site-packages/flask/app.py", line 1381, in handle_user_exception
    reraise(exc_type, exc_value, tb)
  File "/Users/varunshah1106/Documents/ocr-test/env/lib/python2.7/site-packages/flask/app.py", line 1475, in full_dispatch_request
    rv = self.dispatch_request()
  File "/Users/varunshah1106/Documents/ocr-test/env/lib/python2.7/site-packages/flask/app.py", line 1461, in dispatch_request
    return self.view_functions[rule.endpoint](**req.view_args)
  File "app.py", line 29, in ocr
    response = VisionApi().ocr(image.read())
  File "/Users/varunshah1106/Documents/ocr-test/flask_server/ocr.py", line 71, in ocr
    results = service.files().insert(
AttributeError: 'Resource' object has no attribute 'insert'
2016-03-08 03:07:33,215 INFO:             errors [in app.py:64]
2016-03-08 03:07:37,985 ERROR:             Exception on /ocr/ [POST] [in /Users/varunshah1106/Documents/ocr-test/env/lib/python2.7/site-packages/flask/app.py:1423]
Traceback (most recent call last):
  File "/Users/varunshah1106/Documents/ocr-test/env/lib/python2.7/site-packages/flask/app.py", line 1817, in wsgi_app
    response = self.full_dispatch_request()
  File "/Users/varunshah1106/Documents/ocr-test/env/lib/python2.7/site-packages/flask/app.py", line 1477, in full_dispatch_request
    rv = self.handle_user_exception(e)
  File "/Users/varunshah1106/Documents/ocr-test/env/lib/python2.7/site-packages/flask/app.py", line 1381, in handle_user_exception
    reraise(exc_type, exc_value, tb)
  File "/Users/varunshah1106/Documents/ocr-test/env/lib/python2.7/site-packages/flask/app.py", line 1475, in full_dispatch_request
    rv = self.dispatch_request()
  File "/Users/varunshah1106/Documents/ocr-test/env/lib/python2.7/site-packages/flask/app.py", line 1461, in dispatch_request
    return self.view_functions[rule.endpoint](**req.view_args)
  File "app.py", line 29, in ocr
    response = VisionApi().ocr(image.read())
  File "/Users/varunshah1106/Documents/ocr-test/flask_server/ocr.py", line 71, in ocr
    results = service.files().insert(
AttributeError: 'Resource' object has no attribute 'insert'
2016-03-08 03:09:20,460 INFO:             errors [in app.py:64]
2016-03-08 03:09:25,022 ERROR:             Exception on /ocr/ [POST] [in /Users/varunshah1106/Documents/ocr-test/env/lib/python2.7/site-packages/flask/app.py:1423]
Traceback (most recent call last):
  File "/Users/varunshah1106/Documents/ocr-test/env/lib/python2.7/site-packages/flask/app.py", line 1817, in wsgi_app
    response = self.full_dispatch_request()
  File "/Users/varunshah1106/Documents/ocr-test/env/lib/python2.7/site-packages/flask/app.py", line 1477, in full_dispatch_request
    rv = self.handle_user_exception(e)
  File "/Users/varunshah1106/Documents/ocr-test/env/lib/python2.7/site-packages/flask/app.py", line 1381, in handle_user_exception
    reraise(exc_type, exc_value, tb)
  File "/Users/varunshah1106/Documents/ocr-test/env/lib/python2.7/site-packages/flask/app.py", line 1475, in full_dispatch_request
    rv = self.dispatch_request()
  File "/Users/varunshah1106/Documents/ocr-test/env/lib/python2.7/site-packages/flask/app.py", line 1461, in dispatch_request
    return self.view_functions[rule.endpoint](**req.view_args)
  File "app.py", line 29, in ocr
    response = VisionApi().ocr(image.read())
  File "/Users/varunshah1106/Documents/ocr-test/flask_server/ocr.py", line 71, in ocr
    results = service.files().insert(
AttributeError: 'Resource' object has no attribute 'insert'
2016-03-08 03:09:52,466 INFO:             errors [in app.py:64]
2016-03-08 03:09:57,497 ERROR:             Exception on /ocr/ [POST] [in /Users/varunshah1106/Documents/ocr-test/env/lib/python2.7/site-packages/flask/app.py:1423]
Traceback (most recent call last):
  File "/Users/varunshah1106/Documents/ocr-test/env/lib/python2.7/site-packages/flask/app.py", line 1817, in wsgi_app
    response = self.full_dispatch_request()
  File "/Users/varunshah1106/Documents/ocr-test/env/lib/python2.7/site-packages/flask/app.py", line 1477, in full_dispatch_request
    rv = self.handle_user_exception(e)
  File "/Users/varunshah1106/Documents/ocr-test/env/lib/python2.7/site-packages/flask/app.py", line 1381, in handle_user_exception
    reraise(exc_type, exc_value, tb)
  File "/Users/varunshah1106/Documents/ocr-test/env/lib/python2.7/site-packages/flask/app.py", line 1475, in full_dispatch_request
    rv = self.dispatch_request()
  File "/Users/varunshah1106/Documents/ocr-test/env/lib/python2.7/site-packages/flask/app.py", line 1461, in dispatch_request
    return self.view_functions[rule.endpoint](**req.view_args)
  File "app.py", line 29, in ocr
    response = VisionApi().ocr(image.read())
  File "/Users/varunshah1106/Documents/ocr-test/flask_server/ocr.py", line 72, in ocr
    body=body, media_body=media_body).execute()
  File "/Users/varunshah1106/Documents/ocr-test/env/lib/python2.7/site-packages/oauth2client/util.py", line 137, in positional_wrapper
    return wrapped(*args, **kwargs)
  File "/Users/varunshah1106/Documents/ocr-test/env/lib/python2.7/site-packages/googleapiclient/http.py", line 732, in execute
    _, body = self.next_chunk(http=http, num_retries=num_retries)
  File "/Users/varunshah1106/Documents/ocr-test/env/lib/python2.7/site-packages/oauth2client/util.py", line 137, in positional_wrapper
    return wrapped(*args, **kwargs)
  File "/Users/varunshah1106/Documents/ocr-test/env/lib/python2.7/site-packages/googleapiclient/http.py", line 836, in next_chunk
    raise ResumableUploadError(resp, content)
ResumableUploadError: <HttpError 403 "Insufficient Permission">
2016-03-08 03:10:54,241 INFO:             errors [in app.py:64]
2016-03-08 03:11:00,136 ERROR:             Exception on /ocr/ [POST] [in /Users/varunshah1106/Documents/ocr-test/env/lib/python2.7/site-packages/flask/app.py:1423]
Traceback (most recent call last):
  File "/Users/varunshah1106/Documents/ocr-test/env/lib/python2.7/site-packages/flask/app.py", line 1817, in wsgi_app
    response = self.full_dispatch_request()
  File "/Users/varunshah1106/Documents/ocr-test/env/lib/python2.7/site-packages/flask/app.py", line 1477, in full_dispatch_request
    rv = self.handle_user_exception(e)
  File "/Users/varunshah1106/Documents/ocr-test/env/lib/python2.7/site-packages/flask/app.py", line 1381, in handle_user_exception
    reraise(exc_type, exc_value, tb)
  File "/Users/varunshah1106/Documents/ocr-test/env/lib/python2.7/site-packages/flask/app.py", line 1475, in full_dispatch_request
    rv = self.dispatch_request()
  File "/Users/varunshah1106/Documents/ocr-test/env/lib/python2.7/site-packages/flask/app.py", line 1461, in dispatch_request
    return self.view_functions[rule.endpoint](**req.view_args)
  File "app.py", line 29, in ocr
    response = VisionApi().ocr(image.read())
  File "/Users/varunshah1106/Documents/ocr-test/flask_server/ocr.py", line 72, in ocr
    body=body, media_body=media_body).execute()
  File "/Users/varunshah1106/Documents/ocr-test/env/lib/python2.7/site-packages/oauth2client/util.py", line 137, in positional_wrapper
    return wrapped(*args, **kwargs)
  File "/Users/varunshah1106/Documents/ocr-test/env/lib/python2.7/site-packages/googleapiclient/http.py", line 732, in execute
    _, body = self.next_chunk(http=http, num_retries=num_retries)
  File "/Users/varunshah1106/Documents/ocr-test/env/lib/python2.7/site-packages/oauth2client/util.py", line 137, in positional_wrapper
    return wrapped(*args, **kwargs)
  File "/Users/varunshah1106/Documents/ocr-test/env/lib/python2.7/site-packages/googleapiclient/http.py", line 836, in next_chunk
    raise ResumableUploadError(resp, content)
ResumableUploadError: <HttpError 403 "Insufficient Permission">
2016-03-08 03:12:09,192 INFO:             errors [in app.py:64]
2016-03-08 03:12:15,527 ERROR:             Exception on /ocr/ [POST] [in /Users/varunshah1106/Documents/ocr-test/env/lib/python2.7/site-packages/flask/app.py:1423]
Traceback (most recent call last):
  File "/Users/varunshah1106/Documents/ocr-test/env/lib/python2.7/site-packages/flask/app.py", line 1817, in wsgi_app
    response = self.full_dispatch_request()
  File "/Users/varunshah1106/Documents/ocr-test/env/lib/python2.7/site-packages/flask/app.py", line 1477, in full_dispatch_request
    rv = self.handle_user_exception(e)
  File "/Users/varunshah1106/Documents/ocr-test/env/lib/python2.7/site-packages/flask/app.py", line 1381, in handle_user_exception
    reraise(exc_type, exc_value, tb)
  File "/Users/varunshah1106/Documents/ocr-test/env/lib/python2.7/site-packages/flask/app.py", line 1475, in full_dispatch_request
    rv = self.dispatch_request()
  File "/Users/varunshah1106/Documents/ocr-test/env/lib/python2.7/site-packages/flask/app.py", line 1461, in dispatch_request
    return self.view_functions[rule.endpoint](**req.view_args)
  File "app.py", line 29, in ocr
    response = VisionApi().ocr(image.read())
  File "/Users/varunshah1106/Documents/ocr-test/flask_server/ocr.py", line 72, in ocr
    body=body, media_body=media_body).execute()
  File "/Users/varunshah1106/Documents/ocr-test/env/lib/python2.7/site-packages/oauth2client/util.py", line 137, in positional_wrapper
    return wrapped(*args, **kwargs)
  File "/Users/varunshah1106/Documents/ocr-test/env/lib/python2.7/site-packages/googleapiclient/http.py", line 732, in execute
    _, body = self.next_chunk(http=http, num_retries=num_retries)
  File "/Users/varunshah1106/Documents/ocr-test/env/lib/python2.7/site-packages/oauth2client/util.py", line 137, in positional_wrapper
    return wrapped(*args, **kwargs)
  File "/Users/varunshah1106/Documents/ocr-test/env/lib/python2.7/site-packages/googleapiclient/http.py", line 836, in next_chunk
    raise ResumableUploadError(resp, content)
ResumableUploadError: <HttpError 403 "Insufficient Permission">
2016-03-08 03:13:12,495 ERROR:             Exception on /ocr/ [POST] [in /Users/varunshah1106/Documents/ocr-test/env/lib/python2.7/site-packages/flask/app.py:1423]
Traceback (most recent call last):
  File "/Users/varunshah1106/Documents/ocr-test/env/lib/python2.7/site-packages/flask/app.py", line 1817, in wsgi_app
    response = self.full_dispatch_request()
  File "/Users/varunshah1106/Documents/ocr-test/env/lib/python2.7/site-packages/flask/app.py", line 1477, in full_dispatch_request
    rv = self.handle_user_exception(e)
  File "/Users/varunshah1106/Documents/ocr-test/env/lib/python2.7/site-packages/flask/app.py", line 1381, in handle_user_exception
    reraise(exc_type, exc_value, tb)
  File "/Users/varunshah1106/Documents/ocr-test/env/lib/python2.7/site-packages/flask/app.py", line 1475, in full_dispatch_request
    rv = self.dispatch_request()
  File "/Users/varunshah1106/Documents/ocr-test/env/lib/python2.7/site-packages/flask/app.py", line 1461, in dispatch_request
    return self.view_functions[rule.endpoint](**req.view_args)
  File "app.py", line 29, in ocr
    response = VisionApi().ocr(image.read())
  File "/Users/varunshah1106/Documents/ocr-test/flask_server/ocr.py", line 72, in ocr
    body=body, media_body=media_body).execute()
  File "/Users/varunshah1106/Documents/ocr-test/env/lib/python2.7/site-packages/oauth2client/util.py", line 137, in positional_wrapper
    return wrapped(*args, **kwargs)
  File "/Users/varunshah1106/Documents/ocr-test/env/lib/python2.7/site-packages/googleapiclient/http.py", line 732, in execute
    _, body = self.next_chunk(http=http, num_retries=num_retries)
  File "/Users/varunshah1106/Documents/ocr-test/env/lib/python2.7/site-packages/oauth2client/util.py", line 137, in positional_wrapper
    return wrapped(*args, **kwargs)
  File "/Users/varunshah1106/Documents/ocr-test/env/lib/python2.7/site-packages/googleapiclient/http.py", line 836, in next_chunk
    raise ResumableUploadError(resp, content)
ResumableUploadError: <HttpError 403 "Insufficient Permission">
2016-03-08 03:14:28,072 INFO:             errors [in app.py:64]
2016-03-08 03:14:44,887 ERROR:             Exception on /ocr/ [POST] [in /Users/varunshah1106/Documents/ocr-test/env/lib/python2.7/site-packages/flask/app.py:1423]
Traceback (most recent call last):
  File "/Users/varunshah1106/Documents/ocr-test/env/lib/python2.7/site-packages/flask/app.py", line 1817, in wsgi_app
    response = self.full_dispatch_request()
  File "/Users/varunshah1106/Documents/ocr-test/env/lib/python2.7/site-packages/flask/app.py", line 1477, in full_dispatch_request
    rv = self.handle_user_exception(e)
  File "/Users/varunshah1106/Documents/ocr-test/env/lib/python2.7/site-packages/flask/app.py", line 1381, in handle_user_exception
    reraise(exc_type, exc_value, tb)
  File "/Users/varunshah1106/Documents/ocr-test/env/lib/python2.7/site-packages/flask/app.py", line 1475, in full_dispatch_request
    rv = self.dispatch_request()
  File "/Users/varunshah1106/Documents/ocr-test/env/lib/python2.7/site-packages/flask/app.py", line 1461, in dispatch_request
    return self.view_functions[rule.endpoint](**req.view_args)
  File "app.py", line 30, in ocr
    print response['textAnnotations'][0]['description']
TypeError: 'NoneType' object has no attribute '__getitem__'
2016-03-08 03:17:34,241 INFO:             errors [in app.py:64]
2016-03-08 03:17:45,304 ERROR:             Exception on /ocr/ [POST] [in /Users/varunshah1106/Documents/ocr-test/env/lib/python2.7/site-packages/flask/app.py:1423]
Traceback (most recent call last):
  File "/Users/varunshah1106/Documents/ocr-test/env/lib/python2.7/site-packages/flask/app.py", line 1817, in wsgi_app
    response = self.full_dispatch_request()
  File "/Users/varunshah1106/Documents/ocr-test/env/lib/python2.7/site-packages/flask/app.py", line 1477, in full_dispatch_request
    rv = self.handle_user_exception(e)
  File "/Users/varunshah1106/Documents/ocr-test/env/lib/python2.7/site-packages/flask/app.py", line 1381, in handle_user_exception
    reraise(exc_type, exc_value, tb)
  File "/Users/varunshah1106/Documents/ocr-test/env/lib/python2.7/site-packages/flask/app.py", line 1475, in full_dispatch_request
    rv = self.dispatch_request()
  File "/Users/varunshah1106/Documents/ocr-test/env/lib/python2.7/site-packages/flask/app.py", line 1461, in dispatch_request
    return self.view_functions[rule.endpoint](**req.view_args)
  File "app.py", line 30, in ocr
    print response['textAnnotations'][0]['description']
TypeError: 'NoneType' object has no attribute '__getitem__'
2016-03-08 03:18:05,242 INFO:             errors [in app.py:64]
2016-03-08 03:18:08,857 ERROR:             Exception on /ocr/ [POST] [in /Users/varunshah1106/Documents/ocr-test/env/lib/python2.7/site-packages/flask/app.py:1423]
Traceback (most recent call last):
  File "/Users/varunshah1106/Documents/ocr-test/env/lib/python2.7/site-packages/flask/app.py", line 1817, in wsgi_app
    response = self.full_dispatch_request()
  File "/Users/varunshah1106/Documents/ocr-test/env/lib/python2.7/site-packages/flask/app.py", line 1477, in full_dispatch_request
    rv = self.handle_user_exception(e)
  File "/Users/varunshah1106/Documents/ocr-test/env/lib/python2.7/site-packages/flask/app.py", line 1381, in handle_user_exception
    reraise(exc_type, exc_value, tb)
  File "/Users/varunshah1106/Documents/ocr-test/env/lib/python2.7/site-packages/flask/app.py", line 1475, in full_dispatch_request
    rv = self.dispatch_request()
  File "/Users/varunshah1106/Documents/ocr-test/env/lib/python2.7/site-packages/flask/app.py", line 1461, in dispatch_request
    return self.view_functions[rule.endpoint](**req.view_args)
  File "app.py", line 30, in ocr
    print response['textAnnotations'][0]['description']
TypeError: 'NoneType' object has no attribute '__getitem__'
2016-03-08 03:19:01,468 INFO:             errors [in app.py:64]
2016-03-08 03:19:07,722 ERROR:             Exception on /ocr/ [POST] [in /Users/varunshah1106/Documents/ocr-test/env/lib/python2.7/site-packages/flask/app.py:1423]
Traceback (most recent call last):
  File "/Users/varunshah1106/Documents/ocr-test/env/lib/python2.7/site-packages/flask/app.py", line 1817, in wsgi_app
    response = self.full_dispatch_request()
  File "/Users/varunshah1106/Documents/ocr-test/env/lib/python2.7/site-packages/flask/app.py", line 1477, in full_dispatch_request
    rv = self.handle_user_exception(e)
  File "/Users/varunshah1106/Documents/ocr-test/env/lib/python2.7/site-packages/flask/app.py", line 1381, in handle_user_exception
    reraise(exc_type, exc_value, tb)
  File "/Users/varunshah1106/Documents/ocr-test/env/lib/python2.7/site-packages/flask/app.py", line 1475, in full_dispatch_request
    rv = self.dispatch_request()
  File "/Users/varunshah1106/Documents/ocr-test/env/lib/python2.7/site-packages/flask/app.py", line 1461, in dispatch_request
    return self.view_functions[rule.endpoint](**req.view_args)
  File "app.py", line 30, in ocr
    print response['textAnnotations'][0]['description']
TypeError: 'NoneType' object has no attribute '__getitem__'
2016-03-08 03:22:12,578 INFO:             errors [in app.py:64]
2016-03-08 03:22:24,593 ERROR:             Exception on /ocr/ [POST] [in /Users/varunshah1106/Documents/ocr-test/env/lib/python2.7/site-packages/flask/app.py:1423]
Traceback (most recent call last):
  File "/Users/varunshah1106/Documents/ocr-test/env/lib/python2.7/site-packages/flask/app.py", line 1817, in wsgi_app
    response = self.full_dispatch_request()
  File "/Users/varunshah1106/Documents/ocr-test/env/lib/python2.7/site-packages/flask/app.py", line 1477, in full_dispatch_request
    rv = self.handle_user_exception(e)
  File "/Users/varunshah1106/Documents/ocr-test/env/lib/python2.7/site-packages/flask/app.py", line 1381, in handle_user_exception
    reraise(exc_type, exc_value, tb)
  File "/Users/varunshah1106/Documents/ocr-test/env/lib/python2.7/site-packages/flask/app.py", line 1475, in full_dispatch_request
    rv = self.dispatch_request()
  File "/Users/varunshah1106/Documents/ocr-test/env/lib/python2.7/site-packages/flask/app.py", line 1461, in dispatch_request
    return self.view_functions[rule.endpoint](**req.view_args)
  File "app.py", line 30, in ocr
    print response['textAnnotations'][0]['description']
TypeError: 'NoneType' object has no attribute '__getitem__'
2016-03-08 03:23:50,758 INFO:             errors [in app.py:64]
2016-03-08 03:23:59,083 ERROR:             Exception on /ocr/ [POST] [in /Users/varunshah1106/Documents/ocr-test/env/lib/python2.7/site-packages/flask/app.py:1423]
Traceback (most recent call last):
  File "/Users/varunshah1106/Documents/ocr-test/env/lib/python2.7/site-packages/flask/app.py", line 1817, in wsgi_app
    response = self.full_dispatch_request()
  File "/Users/varunshah1106/Documents/ocr-test/env/lib/python2.7/site-packages/flask/app.py", line 1477, in full_dispatch_request
    rv = self.handle_user_exception(e)
  File "/Users/varunshah1106/Documents/ocr-test/env/lib/python2.7/site-packages/flask/app.py", line 1381, in handle_user_exception
    reraise(exc_type, exc_value, tb)
  File "/Users/varunshah1106/Documents/ocr-test/env/lib/python2.7/site-packages/flask/app.py", line 1475, in full_dispatch_request
    rv = self.dispatch_request()
  File "/Users/varunshah1106/Documents/ocr-test/env/lib/python2.7/site-packages/flask/app.py", line 1461, in dispatch_request
    return self.view_functions[rule.endpoint](**req.view_args)
  File "app.py", line 29, in ocr
    response = VisionApi().ocr(image.read())
  File "/Users/varunshah1106/Documents/ocr-test/flask_server/ocr.py", line 71, in ocr
    body=body, media_body=media_body, ocr=True).execute()
  File "/Users/varunshah1106/Documents/ocr-test/env/lib/python2.7/site-packages/googleapiclient/discovery.py", line 676, in method
    raise TypeError('Got an unexpected keyword argument "%s"' % name)
TypeError: Got an unexpected keyword argument "ocr"
2016-03-08 03:24:32,089 INFO:             errors [in app.py:64]
2016-03-08 03:24:37,032 ERROR:             Exception on /ocr/ [POST] [in /Users/varunshah1106/Documents/ocr-test/env/lib/python2.7/site-packages/flask/app.py:1423]
Traceback (most recent call last):
  File "/Users/varunshah1106/Documents/ocr-test/env/lib/python2.7/site-packages/flask/app.py", line 1817, in wsgi_app
    response = self.full_dispatch_request()
  File "/Users/varunshah1106/Documents/ocr-test/env/lib/python2.7/site-packages/flask/app.py", line 1477, in full_dispatch_request
    rv = self.handle_user_exception(e)
  File "/Users/varunshah1106/Documents/ocr-test/env/lib/python2.7/site-packages/flask/app.py", line 1381, in handle_user_exception
    reraise(exc_type, exc_value, tb)
  File "/Users/varunshah1106/Documents/ocr-test/env/lib/python2.7/site-packages/flask/app.py", line 1475, in full_dispatch_request
    rv = self.dispatch_request()
  File "/Users/varunshah1106/Documents/ocr-test/env/lib/python2.7/site-packages/flask/app.py", line 1461, in dispatch_request
    return self.view_functions[rule.endpoint](**req.view_args)
  File "app.py", line 30, in ocr
    print response['textAnnotations'][0]['description']
TypeError: 'NoneType' object has no attribute '__getitem__'
2016-03-08 03:25:02,362 INFO:             errors [in app.py:64]
2016-03-08 03:25:07,363 ERROR:             Exception on /ocr/ [POST] [in /Users/varunshah1106/Documents/ocr-test/env/lib/python2.7/site-packages/flask/app.py:1423]
Traceback (most recent call last):
  File "/Users/varunshah1106/Documents/ocr-test/env/lib/python2.7/site-packages/flask/app.py", line 1817, in wsgi_app
    response = self.full_dispatch_request()
  File "/Users/varunshah1106/Documents/ocr-test/env/lib/python2.7/site-packages/flask/app.py", line 1477, in full_dispatch_request
    rv = self.handle_user_exception(e)
  File "/Users/varunshah1106/Documents/ocr-test/env/lib/python2.7/site-packages/flask/app.py", line 1381, in handle_user_exception
    reraise(exc_type, exc_value, tb)
  File "/Users/varunshah1106/Documents/ocr-test/env/lib/python2.7/site-packages/flask/app.py", line 1475, in full_dispatch_request
    rv = self.dispatch_request()
  File "/Users/varunshah1106/Documents/ocr-test/env/lib/python2.7/site-packages/flask/app.py", line 1461, in dispatch_request
    return self.view_functions[rule.endpoint](**req.view_args)
  File "app.py", line 30, in ocr
    print response['textAnnotations'][0]['description']
TypeError: 'NoneType' object has no attribute '__getitem__'
2016-03-08 03:31:37,563 INFO:             errors [in app.py:64]
2016-03-08 03:31:47,556 ERROR:             Exception on /ocr/ [POST] [in /Users/varunshah1106/Documents/ocr-test/env/lib/python2.7/site-packages/flask/app.py:1423]
Traceback (most recent call last):
  File "/Users/varunshah1106/Documents/ocr-test/env/lib/python2.7/site-packages/flask/app.py", line 1817, in wsgi_app
    response = self.full_dispatch_request()
  File "/Users/varunshah1106/Documents/ocr-test/env/lib/python2.7/site-packages/flask/app.py", line 1477, in full_dispatch_request
    rv = self.handle_user_exception(e)
  File "/Users/varunshah1106/Documents/ocr-test/env/lib/python2.7/site-packages/flask/app.py", line 1381, in handle_user_exception
    reraise(exc_type, exc_value, tb)
  File "/Users/varunshah1106/Documents/ocr-test/env/lib/python2.7/site-packages/flask/app.py", line 1475, in full_dispatch_request
    rv = self.dispatch_request()
  File "/Users/varunshah1106/Documents/ocr-test/env/lib/python2.7/site-packages/flask/app.py", line 1461, in dispatch_request
    return self.view_functions[rule.endpoint](**req.view_args)
  File "app.py", line 30, in ocr
    print response['textAnnotations'][0]['description']
TypeError: 'NoneType' object has no attribute '__getitem__'
2016-03-08 03:33:08,243 INFO:             errors [in app.py:64]
2016-03-08 03:33:12,854 ERROR:             Exception on /ocr/ [POST] [in /Users/varunshah1106/Documents/ocr-test/env/lib/python2.7/site-packages/flask/app.py:1423]
Traceback (most recent call last):
  File "/Users/varunshah1106/Documents/ocr-test/env/lib/python2.7/site-packages/flask/app.py", line 1817, in wsgi_app
    response = self.full_dispatch_request()
  File "/Users/varunshah1106/Documents/ocr-test/env/lib/python2.7/site-packages/flask/app.py", line 1477, in full_dispatch_request
    rv = self.handle_user_exception(e)
  File "/Users/varunshah1106/Documents/ocr-test/env/lib/python2.7/site-packages/flask/app.py", line 1381, in handle_user_exception
    reraise(exc_type, exc_value, tb)
  File "/Users/varunshah1106/Documents/ocr-test/env/lib/python2.7/site-packages/flask/app.py", line 1475, in full_dispatch_request
    rv = self.dispatch_request()
  File "/Users/varunshah1106/Documents/ocr-test/env/lib/python2.7/site-packages/flask/app.py", line 1461, in dispatch_request
    return self.view_functions[rule.endpoint](**req.view_args)
  File "app.py", line 29, in ocr
    response = VisionApi().ocr(image.read())
  File "/Users/varunshah1106/Documents/ocr-test/flask_server/ocr.py", line 76, in ocr
    ocr=True
  File "/Users/varunshah1106/Documents/ocr-test/env/lib/python2.7/site-packages/googleapiclient/discovery.py", line 676, in method
    raise TypeError('Got an unexpected keyword argument "%s"' % name)
TypeError: Got an unexpected keyword argument "ocr"
2016-03-08 03:35:40,695 INFO:             errors [in app.py:64]
2016-03-08 03:35:50,858 ERROR:             Exception on /ocr/ [POST] [in /Users/varunshah1106/Documents/ocr-test/env/lib/python2.7/site-packages/flask/app.py:1423]
Traceback (most recent call last):
  File "/Users/varunshah1106/Documents/ocr-test/env/lib/python2.7/site-packages/flask/app.py", line 1817, in wsgi_app
    response = self.full_dispatch_request()
  File "/Users/varunshah1106/Documents/ocr-test/env/lib/python2.7/site-packages/flask/app.py", line 1477, in full_dispatch_request
    rv = self.handle_user_exception(e)
  File "/Users/varunshah1106/Documents/ocr-test/env/lib/python2.7/site-packages/flask/app.py", line 1381, in handle_user_exception
    reraise(exc_type, exc_value, tb)
  File "/Users/varunshah1106/Documents/ocr-test/env/lib/python2.7/site-packages/flask/app.py", line 1475, in full_dispatch_request
    rv = self.dispatch_request()
  File "/Users/varunshah1106/Documents/ocr-test/env/lib/python2.7/site-packages/flask/app.py", line 1461, in dispatch_request
    return self.view_functions[rule.endpoint](**req.view_args)
  File "app.py", line 29, in ocr
    response = VisionApi().ocr(image.read())
  File "/Users/varunshah1106/Documents/ocr-test/flask_server/ocr.py", line 75, in ocr
    print(dir(service.files().insert()))
AttributeError: 'Resource' object has no attribute 'insert'
2016-03-08 03:36:04,217 INFO:             errors [in app.py:64]
2016-03-08 03:36:07,367 ERROR:             Exception on /ocr/ [POST] [in /Users/varunshah1106/Documents/ocr-test/env/lib/python2.7/site-packages/flask/app.py:1423]
Traceback (most recent call last):
  File "/Users/varunshah1106/Documents/ocr-test/env/lib/python2.7/site-packages/flask/app.py", line 1817, in wsgi_app
    response = self.full_dispatch_request()
  File "/Users/varunshah1106/Documents/ocr-test/env/lib/python2.7/site-packages/flask/app.py", line 1477, in full_dispatch_request
    rv = self.handle_user_exception(e)
  File "/Users/varunshah1106/Documents/ocr-test/env/lib/python2.7/site-packages/flask/app.py", line 1381, in handle_user_exception
    reraise(exc_type, exc_value, tb)
  File "/Users/varunshah1106/Documents/ocr-test/env/lib/python2.7/site-packages/flask/app.py", line 1475, in full_dispatch_request
    rv = self.dispatch_request()
  File "/Users/varunshah1106/Documents/ocr-test/env/lib/python2.7/site-packages/flask/app.py", line 1461, in dispatch_request
    return self.view_functions[rule.endpoint](**req.view_args)
  File "app.py", line 30, in ocr
    print response['textAnnotations'][0]['description']
TypeError: 'NoneType' object has no attribute '__getitem__'
2016-03-08 03:53:14,792 INFO:             errors [in app.py:64]
2016-03-08 03:53:39,491 ERROR:             Exception on /ocr/ [POST] [in /Users/varunshah1106/Documents/ocr-test/env/lib/python2.7/site-packages/flask/app.py:1423]
Traceback (most recent call last):
  File "/Users/varunshah1106/Documents/ocr-test/env/lib/python2.7/site-packages/flask/app.py", line 1817, in wsgi_app
    response = self.full_dispatch_request()
  File "/Users/varunshah1106/Documents/ocr-test/env/lib/python2.7/site-packages/flask/app.py", line 1477, in full_dispatch_request
    rv = self.handle_user_exception(e)
  File "/Users/varunshah1106/Documents/ocr-test/env/lib/python2.7/site-packages/flask/app.py", line 1381, in handle_user_exception
    reraise(exc_type, exc_value, tb)
  File "/Users/varunshah1106/Documents/ocr-test/env/lib/python2.7/site-packages/flask/app.py", line 1475, in full_dispatch_request
    rv = self.dispatch_request()
  File "/Users/varunshah1106/Documents/ocr-test/env/lib/python2.7/site-packages/flask/app.py", line 1461, in dispatch_request
    return self.view_functions[rule.endpoint](**req.view_args)
  File "app.py", line 30, in ocr
    print response['textAnnotations'][0]['description']
TypeError: 'NoneType' object has no attribute '__getitem__'
2016-03-08 03:54:40,459 INFO:             errors [in app.py:64]
2016-03-08 03:54:45,215 ERROR:             Exception on /ocr/ [POST] [in /Users/varunshah1106/Documents/ocr-test/env/lib/python2.7/site-packages/flask/app.py:1423]
Traceback (most recent call last):
  File "/Users/varunshah1106/Documents/ocr-test/env/lib/python2.7/site-packages/flask/app.py", line 1817, in wsgi_app
    response = self.full_dispatch_request()
  File "/Users/varunshah1106/Documents/ocr-test/env/lib/python2.7/site-packages/flask/app.py", line 1477, in full_dispatch_request
    rv = self.handle_user_exception(e)
  File "/Users/varunshah1106/Documents/ocr-test/env/lib/python2.7/site-packages/flask/app.py", line 1381, in handle_user_exception
    reraise(exc_type, exc_value, tb)
  File "/Users/varunshah1106/Documents/ocr-test/env/lib/python2.7/site-packages/flask/app.py", line 1475, in full_dispatch_request
    rv = self.dispatch_request()
  File "/Users/varunshah1106/Documents/ocr-test/env/lib/python2.7/site-packages/flask/app.py", line 1461, in dispatch_request
    return self.view_functions[rule.endpoint](**req.view_args)
  File "app.py", line 30, in ocr
    print response['textAnnotations'][0]['description']
TypeError: 'NoneType' object has no attribute '__getitem__'
2016-03-08 04:00:10,999 INFO:             errors [in app.py:64]
2016-03-08 04:00:18,123 ERROR:             Exception on /ocr/ [POST] [in /Users/varunshah1106/Documents/ocr-test/env/lib/python2.7/site-packages/flask/app.py:1423]
Traceback (most recent call last):
  File "/Users/varunshah1106/Documents/ocr-test/env/lib/python2.7/site-packages/flask/app.py", line 1817, in wsgi_app
    response = self.full_dispatch_request()
  File "/Users/varunshah1106/Documents/ocr-test/env/lib/python2.7/site-packages/flask/app.py", line 1477, in full_dispatch_request
    rv = self.handle_user_exception(e)
  File "/Users/varunshah1106/Documents/ocr-test/env/lib/python2.7/site-packages/flask/app.py", line 1381, in handle_user_exception
    reraise(exc_type, exc_value, tb)
  File "/Users/varunshah1106/Documents/ocr-test/env/lib/python2.7/site-packages/flask/app.py", line 1475, in full_dispatch_request
    rv = self.dispatch_request()
  File "/Users/varunshah1106/Documents/ocr-test/env/lib/python2.7/site-packages/flask/app.py", line 1461, in dispatch_request
    return self.view_functions[rule.endpoint](**req.view_args)
  File "app.py", line 29, in ocr
    response = VisionApi().ocr(image.read())
  File "/Users/varunshah1106/Documents/ocr-test/flask_server/ocr.py", line 76, in ocr
    body=body, media_body=media_body, convert=True).execute()
  File "/Users/varunshah1106/Documents/ocr-test/env/lib/python2.7/site-packages/googleapiclient/discovery.py", line 676, in method
    raise TypeError('Got an unexpected keyword argument "%s"' % name)
TypeError: Got an unexpected keyword argument "convert"
2016-03-08 04:02:01,800 INFO:             errors [in app.py:64]
2016-03-08 04:02:06,142 ERROR:             Exception on /ocr/ [POST] [in /Users/varunshah1106/Documents/ocr-test/env/lib/python2.7/site-packages/flask/app.py:1423]
Traceback (most recent call last):
  File "/Users/varunshah1106/Documents/ocr-test/env/lib/python2.7/site-packages/flask/app.py", line 1817, in wsgi_app
    response = self.full_dispatch_request()
  File "/Users/varunshah1106/Documents/ocr-test/env/lib/python2.7/site-packages/flask/app.py", line 1477, in full_dispatch_request
    rv = self.handle_user_exception(e)
  File "/Users/varunshah1106/Documents/ocr-test/env/lib/python2.7/site-packages/flask/app.py", line 1381, in handle_user_exception
    reraise(exc_type, exc_value, tb)
  File "/Users/varunshah1106/Documents/ocr-test/env/lib/python2.7/site-packages/flask/app.py", line 1475, in full_dispatch_request
    rv = self.dispatch_request()
  File "/Users/varunshah1106/Documents/ocr-test/env/lib/python2.7/site-packages/flask/app.py", line 1461, in dispatch_request
    return self.view_functions[rule.endpoint](**req.view_args)
  File "app.py", line 29, in ocr
    response = VisionApi().ocr(image.read())
  File "/Users/varunshah1106/Documents/ocr-test/flask_server/ocr.py", line 76, in ocr
    body=body, media_body=media_body, convert=True).execute()
  File "/Users/varunshah1106/Documents/ocr-test/env/lib/python2.7/site-packages/googleapiclient/discovery.py", line 676, in method
    raise TypeError('Got an unexpected keyword argument "%s"' % name)
TypeError: Got an unexpected keyword argument "convert"
2016-03-08 18:08:39,603 INFO:             errors [in app.py:64]
2016-03-08 18:08:47,198 ERROR:             Exception on /ocr/ [POST] [in /Users/varunshah1106/Documents/ocr-test/env/lib/python2.7/site-packages/flask/app.py:1423]
Traceback (most recent call last):
  File "/Users/varunshah1106/Documents/ocr-test/env/lib/python2.7/site-packages/flask/app.py", line 1817, in wsgi_app
    response = self.full_dispatch_request()
  File "/Users/varunshah1106/Documents/ocr-test/env/lib/python2.7/site-packages/flask/app.py", line 1477, in full_dispatch_request
    rv = self.handle_user_exception(e)
  File "/Users/varunshah1106/Documents/ocr-test/env/lib/python2.7/site-packages/flask/app.py", line 1381, in handle_user_exception
    reraise(exc_type, exc_value, tb)
  File "/Users/varunshah1106/Documents/ocr-test/env/lib/python2.7/site-packages/flask/app.py", line 1475, in full_dispatch_request
    rv = self.dispatch_request()
  File "/Users/varunshah1106/Documents/ocr-test/env/lib/python2.7/site-packages/flask/app.py", line 1461, in dispatch_request
    return self.view_functions[rule.endpoint](**req.view_args)
  File "app.py", line 29, in ocr
    response = VisionApi().ocr(image.read())
  File "/Users/varunshah1106/Documents/ocr-test/flask_server/ocr.py", line 64, in ocr
    print(image_to_string(Image.open('temp.jpg'), lang='sa'))
  File "/Users/varunshah1106/Documents/ocr-test/env/lib/python2.7/site-packages/pytesseract/pytesseract.py", line 142, in image_to_string
    config=config)
  File "/Users/varunshah1106/Documents/ocr-test/env/lib/python2.7/site-packages/pytesseract/pytesseract.py", line 75, in run_tesseract
    stderr=subprocess.PIPE)
  File "/System/Library/Frameworks/Python.framework/Versions/2.7/lib/python2.7/subprocess.py", line 710, in __init__
    errread, errwrite)
  File "/System/Library/Frameworks/Python.framework/Versions/2.7/lib/python2.7/subprocess.py", line 1335, in _execute_child
    raise child_exception
OSError: [Errno 2] No such file or directory
