2016-03-07 03:33:27,615 INFO:             errors [in app.py:52]
2016-03-07 03:33:36,249 ERROR:             Exception on /v1/ocr [POST] [in /Users/varunshah1106/Documents/.ocr/lib/python2.7/site-packages/flask/app.py:1423]
Traceback (most recent call last):
  File "/Users/varunshah1106/Documents/.ocr/lib/python2.7/site-packages/flask/app.py", line 1817, in wsgi_app
    response = self.full_dispatch_request()
  File "/Users/varunshah1106/Documents/.ocr/lib/python2.7/site-packages/flask/app.py", line 1477, in full_dispatch_request
    rv = self.handle_user_exception(e)
  File "/Users/varunshah1106/Documents/.ocr/lib/python2.7/site-packages/flask/app.py", line 1381, in handle_user_exception
    reraise(exc_type, exc_value, tb)
  File "/Users/varunshah1106/Documents/.ocr/lib/python2.7/site-packages/flask/app.py", line 1475, in full_dispatch_request
    rv = self.dispatch_request()
  File "/Users/varunshah1106/Documents/.ocr/lib/python2.7/site-packages/flask/app.py", line 1461, in dispatch_request
    return self.view_functions[rule.endpoint](**req.view_args)
  File "app.py", line 19, in ocr
    data = load_data_From_url
NameError: global name 'load_data_From_url' is not defined
2016-03-07 03:33:37,776 ERROR:             Exception on /v1/ocr [POST] [in /Users/varunshah1106/Documents/.ocr/lib/python2.7/site-packages/flask/app.py:1423]
Traceback (most recent call last):
  File "/Users/varunshah1106/Documents/.ocr/lib/python2.7/site-packages/flask/app.py", line 1817, in wsgi_app
    response = self.full_dispatch_request()
  File "/Users/varunshah1106/Documents/.ocr/lib/python2.7/site-packages/flask/app.py", line 1477, in full_dispatch_request
    rv = self.handle_user_exception(e)
  File "/Users/varunshah1106/Documents/.ocr/lib/python2.7/site-packages/flask/app.py", line 1381, in handle_user_exception
    reraise(exc_type, exc_value, tb)
  File "/Users/varunshah1106/Documents/.ocr/lib/python2.7/site-packages/flask/app.py", line 1475, in full_dispatch_request
    rv = self.dispatch_request()
  File "/Users/varunshah1106/Documents/.ocr/lib/python2.7/site-packages/flask/app.py", line 1461, in dispatch_request
    return self.view_functions[rule.endpoint](**req.view_args)
  File "app.py", line 19, in ocr
    data = load_data_From_url
NameError: global name 'load_data_From_url' is not defined
2016-03-07 03:33:38,293 ERROR:             Exception on /v1/ocr [POST] [in /Users/varunshah1106/Documents/.ocr/lib/python2.7/site-packages/flask/app.py:1423]
Traceback (most recent call last):
  File "/Users/varunshah1106/Documents/.ocr/lib/python2.7/site-packages/flask/app.py", line 1817, in wsgi_app
    response = self.full_dispatch_request()
  File "/Users/varunshah1106/Documents/.ocr/lib/python2.7/site-packages/flask/app.py", line 1477, in full_dispatch_request
    rv = self.handle_user_exception(e)
  File "/Users/varunshah1106/Documents/.ocr/lib/python2.7/site-packages/flask/app.py", line 1381, in handle_user_exception
    reraise(exc_type, exc_value, tb)
  File "/Users/varunshah1106/Documents/.ocr/lib/python2.7/site-packages/flask/app.py", line 1475, in full_dispatch_request
    rv = self.dispatch_request()
  File "/Users/varunshah1106/Documents/.ocr/lib/python2.7/site-packages/flask/app.py", line 1461, in dispatch_request
    return self.view_functions[rule.endpoint](**req.view_args)
  File "app.py", line 19, in ocr
    data = load_data_From_url
NameError: global name 'load_data_From_url' is not defined
2016-03-07 03:33:39,596 ERROR:             Exception on /v1/ocr [POST] [in /Users/varunshah1106/Documents/.ocr/lib/python2.7/site-packages/flask/app.py:1423]
Traceback (most recent call last):
  File "/Users/varunshah1106/Documents/.ocr/lib/python2.7/site-packages/flask/app.py", line 1817, in wsgi_app
    response = self.full_dispatch_request()
  File "/Users/varunshah1106/Documents/.ocr/lib/python2.7/site-packages/flask/app.py", line 1477, in full_dispatch_request
    rv = self.handle_user_exception(e)
  File "/Users/varunshah1106/Documents/.ocr/lib/python2.7/site-packages/flask/app.py", line 1381, in handle_user_exception
    reraise(exc_type, exc_value, tb)
  File "/Users/varunshah1106/Documents/.ocr/lib/python2.7/site-packages/flask/app.py", line 1475, in full_dispatch_request
    rv = self.dispatch_request()
  File "/Users/varunshah1106/Documents/.ocr/lib/python2.7/site-packages/flask/app.py", line 1461, in dispatch_request
    return self.view_functions[rule.endpoint](**req.view_args)
  File "app.py", line 19, in ocr
    data = load_data_From_url
NameError: global name 'load_data_From_url' is not defined
2016-03-07 03:37:18,206 INFO:             errors [in app.py:52]
2016-03-07 03:42:13,093 INFO:             errors [in app.py:54]
2016-03-07 03:42:21,041 ERROR:             Exception on /ocr/ [POST] [in /Users/varunshah1106/Documents/.ocr/lib/python2.7/site-packages/flask/app.py:1423]
Traceback (most recent call last):
  File "/Users/varunshah1106/Documents/.ocr/lib/python2.7/site-packages/flask/app.py", line 1817, in wsgi_app
    response = self.full_dispatch_request()
  File "/Users/varunshah1106/Documents/.ocr/lib/python2.7/site-packages/flask/app.py", line 1477, in full_dispatch_request
    rv = self.handle_user_exception(e)
  File "/Users/varunshah1106/Documents/.ocr/lib/python2.7/site-packages/flask/app.py", line 1381, in handle_user_exception
    reraise(exc_type, exc_value, tb)
  File "/Users/varunshah1106/Documents/.ocr/lib/python2.7/site-packages/flask/app.py", line 1475, in full_dispatch_request
    rv = self.dispatch_request()
  File "/Users/varunshah1106/Documents/.ocr/lib/python2.7/site-packages/flask/app.py", line 1461, in dispatch_request
    return self.view_functions[rule.endpoint](**req.view_args)
  File "app.py", line 22, in ocr
    response = VisionApi().detect_text(data)
  File "/Users/varunshah1106/Documents/ocr-test/flask_server/ocr.py", line 21, in __init__
    self.credentials = GoogleCredentials.get_application_default()
  File "/Users/varunshah1106/Documents/.ocr/lib/python2.7/site-packages/oauth2client/client.py", line 1384, in get_application_default
    return GoogleCredentials._get_implicit_credentials()
  File "/Users/varunshah1106/Documents/.ocr/lib/python2.7/site-packages/oauth2client/client.py", line 1374, in _get_implicit_credentials
    raise ApplicationDefaultCredentialsError(ADC_HELP_MSG)
ApplicationDefaultCredentialsError: The Application Default Credentials are not available. They are available if running in Google Compute Engine. Otherwise, the environment variable GOOGLE_APPLICATION_CREDENTIALS must be defined pointing to a file defining the credentials. See https://developers.google.com/accounts/docs/application-default-credentials for more information.
2016-03-07 03:43:13,903 ERROR:             Exception on /ocr/ [POST] [in /Users/varunshah1106/Documents/.ocr/lib/python2.7/site-packages/flask/app.py:1423]
Traceback (most recent call last):
  File "/Users/varunshah1106/Documents/.ocr/lib/python2.7/site-packages/flask/app.py", line 1817, in wsgi_app
    response = self.full_dispatch_request()
  File "/Users/varunshah1106/Documents/.ocr/lib/python2.7/site-packages/flask/app.py", line 1477, in full_dispatch_request
    rv = self.handle_user_exception(e)
  File "/Users/varunshah1106/Documents/.ocr/lib/python2.7/site-packages/flask/app.py", line 1381, in handle_user_exception
    reraise(exc_type, exc_value, tb)
  File "/Users/varunshah1106/Documents/.ocr/lib/python2.7/site-packages/flask/app.py", line 1475, in full_dispatch_request
    rv = self.dispatch_request()
  File "/Users/varunshah1106/Documents/.ocr/lib/python2.7/site-packages/flask/app.py", line 1461, in dispatch_request
    return self.view_functions[rule.endpoint](**req.view_args)
  File "app.py", line 22, in ocr
    response = VisionApi().detect_text(data)
  File "/Users/varunshah1106/Documents/ocr-test/flask_server/ocr.py", line 21, in __init__
    self.credentials = GoogleCredentials.get_application_default()
  File "/Users/varunshah1106/Documents/.ocr/lib/python2.7/site-packages/oauth2client/client.py", line 1384, in get_application_default
    return GoogleCredentials._get_implicit_credentials()
  File "/Users/varunshah1106/Documents/.ocr/lib/python2.7/site-packages/oauth2client/client.py", line 1374, in _get_implicit_credentials
    raise ApplicationDefaultCredentialsError(ADC_HELP_MSG)
ApplicationDefaultCredentialsError: The Application Default Credentials are not available. They are available if running in Google Compute Engine. Otherwise, the environment variable GOOGLE_APPLICATION_CREDENTIALS must be defined pointing to a file defining the credentials. See https://developers.google.com/accounts/docs/application-default-credentials for more information.
2016-03-07 03:43:30,733 INFO:             errors [in app.py:54]
2016-03-07 03:43:35,135 ERROR:             Exception on /ocr/ [POST] [in /Users/varunshah1106/Documents/.ocr/lib/python2.7/site-packages/flask/app.py:1423]
Traceback (most recent call last):
  File "/Users/varunshah1106/Documents/.ocr/lib/python2.7/site-packages/flask/app.py", line 1817, in wsgi_app
    response = self.full_dispatch_request()
  File "/Users/varunshah1106/Documents/.ocr/lib/python2.7/site-packages/flask/app.py", line 1477, in full_dispatch_request
    rv = self.handle_user_exception(e)
  File "/Users/varunshah1106/Documents/.ocr/lib/python2.7/site-packages/flask/app.py", line 1381, in handle_user_exception
    reraise(exc_type, exc_value, tb)
  File "/Users/varunshah1106/Documents/.ocr/lib/python2.7/site-packages/flask/app.py", line 1475, in full_dispatch_request
    rv = self.dispatch_request()
  File "/Users/varunshah1106/Documents/.ocr/lib/python2.7/site-packages/flask/app.py", line 1461, in dispatch_request
    return self.view_functions[rule.endpoint](**req.view_args)
  File "app.py", line 22, in ocr
    response = VisionApi().detect_text(data)
  File "/Users/varunshah1106/Documents/ocr-test/flask_server/ocr.py", line 21, in __init__
    self.credentials = GoogleCredentials.get_application_default()
  File "/Users/varunshah1106/Documents/.ocr/lib/python2.7/site-packages/oauth2client/client.py", line 1384, in get_application_default
    return GoogleCredentials._get_implicit_credentials()
  File "/Users/varunshah1106/Documents/.ocr/lib/python2.7/site-packages/oauth2client/client.py", line 1374, in _get_implicit_credentials
    raise ApplicationDefaultCredentialsError(ADC_HELP_MSG)
ApplicationDefaultCredentialsError: The Application Default Credentials are not available. They are available if running in Google Compute Engine. Otherwise, the environment variable GOOGLE_APPLICATION_CREDENTIALS must be defined pointing to a file defining the credentials. See https://developers.google.com/accounts/docs/application-default-credentials for more information.
2016-03-07 03:44:24,647 INFO:             errors [in app.py:56]
2016-03-07 03:44:30,172 ERROR:             Exception on /ocr/ [POST] [in /Users/varunshah1106/Documents/.ocr/lib/python2.7/site-packages/flask/app.py:1423]
Traceback (most recent call last):
  File "/Users/varunshah1106/Documents/.ocr/lib/python2.7/site-packages/flask/app.py", line 1817, in wsgi_app
    response = self.full_dispatch_request()
  File "/Users/varunshah1106/Documents/.ocr/lib/python2.7/site-packages/flask/app.py", line 1477, in full_dispatch_request
    rv = self.handle_user_exception(e)
  File "/Users/varunshah1106/Documents/.ocr/lib/python2.7/site-packages/flask/app.py", line 1381, in handle_user_exception
    reraise(exc_type, exc_value, tb)
  File "/Users/varunshah1106/Documents/.ocr/lib/python2.7/site-packages/flask/app.py", line 1475, in full_dispatch_request
    rv = self.dispatch_request()
  File "/Users/varunshah1106/Documents/.ocr/lib/python2.7/site-packages/flask/app.py", line 1461, in dispatch_request
    return self.view_functions[rule.endpoint](**req.view_args)
  File "app.py", line 24, in ocr
    response = VisionApi().detect_text(data)
  File "/Users/varunshah1106/Documents/ocr-test/flask_server/ocr.py", line 21, in __init__
    self.credentials = GoogleCredentials.get_application_default()
  File "/Users/varunshah1106/Documents/.ocr/lib/python2.7/site-packages/oauth2client/client.py", line 1384, in get_application_default
    return GoogleCredentials._get_implicit_credentials()
  File "/Users/varunshah1106/Documents/.ocr/lib/python2.7/site-packages/oauth2client/client.py", line 1374, in _get_implicit_credentials
    raise ApplicationDefaultCredentialsError(ADC_HELP_MSG)
ApplicationDefaultCredentialsError: The Application Default Credentials are not available. They are available if running in Google Compute Engine. Otherwise, the environment variable GOOGLE_APPLICATION_CREDENTIALS must be defined pointing to a file defining the credentials. See https://developers.google.com/accounts/docs/application-default-credentials for more information.
2016-03-07 03:44:52,162 ERROR:             Exception on /ocr/ [POST] [in /Users/varunshah1106/Documents/.ocr/lib/python2.7/site-packages/flask/app.py:1423]
Traceback (most recent call last):
  File "/Users/varunshah1106/Documents/.ocr/lib/python2.7/site-packages/flask/app.py", line 1817, in wsgi_app
    response = self.full_dispatch_request()
  File "/Users/varunshah1106/Documents/.ocr/lib/python2.7/site-packages/flask/app.py", line 1477, in full_dispatch_request
    rv = self.handle_user_exception(e)
  File "/Users/varunshah1106/Documents/.ocr/lib/python2.7/site-packages/flask/app.py", line 1381, in handle_user_exception
    reraise(exc_type, exc_value, tb)
  File "/Users/varunshah1106/Documents/.ocr/lib/python2.7/site-packages/flask/app.py", line 1475, in full_dispatch_request
    rv = self.dispatch_request()
  File "/Users/varunshah1106/Documents/.ocr/lib/python2.7/site-packages/flask/app.py", line 1461, in dispatch_request
    return self.view_functions[rule.endpoint](**req.view_args)
  File "app.py", line 24, in ocr
    response = VisionApi().detect_text(data)
  File "/Users/varunshah1106/Documents/ocr-test/flask_server/ocr.py", line 21, in __init__
    self.credentials = GoogleCredentials.get_application_default()
  File "/Users/varunshah1106/Documents/.ocr/lib/python2.7/site-packages/oauth2client/client.py", line 1384, in get_application_default
    return GoogleCredentials._get_implicit_credentials()
  File "/Users/varunshah1106/Documents/.ocr/lib/python2.7/site-packages/oauth2client/client.py", line 1374, in _get_implicit_credentials
    raise ApplicationDefaultCredentialsError(ADC_HELP_MSG)
ApplicationDefaultCredentialsError: The Application Default Credentials are not available. They are available if running in Google Compute Engine. Otherwise, the environment variable GOOGLE_APPLICATION_CREDENTIALS must be defined pointing to a file defining the credentials. See https://developers.google.com/accounts/docs/application-default-credentials for more information.
2016-03-07 03:45:09,747 INFO:             errors [in app.py:56]
2016-03-07 03:45:28,043 ERROR:             Exception on /ocr/ [POST] [in /Users/varunshah1106/Documents/.ocr/lib/python2.7/site-packages/flask/app.py:1423]
Traceback (most recent call last):
  File "/Users/varunshah1106/Documents/.ocr/lib/python2.7/site-packages/flask/app.py", line 1817, in wsgi_app
    response = self.full_dispatch_request()
  File "/Users/varunshah1106/Documents/.ocr/lib/python2.7/site-packages/flask/app.py", line 1477, in full_dispatch_request
    rv = self.handle_user_exception(e)
  File "/Users/varunshah1106/Documents/.ocr/lib/python2.7/site-packages/flask/app.py", line 1381, in handle_user_exception
    reraise(exc_type, exc_value, tb)
  File "/Users/varunshah1106/Documents/.ocr/lib/python2.7/site-packages/flask/app.py", line 1475, in full_dispatch_request
    rv = self.dispatch_request()
  File "/Users/varunshah1106/Documents/.ocr/lib/python2.7/site-packages/flask/app.py", line 1461, in dispatch_request
    return self.view_functions[rule.endpoint](**req.view_args)
  File "app.py", line 21, in ocr
    print request._get_file_stream()
TypeError: _get_file_stream() takes at least 3 arguments (1 given)
2016-03-07 03:46:21,605 INFO:             errors [in app.py:56]
2016-03-07 03:46:33,984 ERROR:             Exception on /ocr/ [POST] [in /Users/varunshah1106/Documents/.ocr/lib/python2.7/site-packages/flask/app.py:1423]
Traceback (most recent call last):
  File "/Users/varunshah1106/Documents/.ocr/lib/python2.7/site-packages/flask/app.py", line 1817, in wsgi_app
    response = self.full_dispatch_request()
  File "/Users/varunshah1106/Documents/.ocr/lib/python2.7/site-packages/flask/app.py", line 1477, in full_dispatch_request
    rv = self.handle_user_exception(e)
  File "/Users/varunshah1106/Documents/.ocr/lib/python2.7/site-packages/flask/app.py", line 1381, in handle_user_exception
    reraise(exc_type, exc_value, tb)
  File "/Users/varunshah1106/Documents/.ocr/lib/python2.7/site-packages/flask/app.py", line 1475, in full_dispatch_request
    rv = self.dispatch_request()
  File "/Users/varunshah1106/Documents/.ocr/lib/python2.7/site-packages/flask/app.py", line 1461, in dispatch_request
    return self.view_functions[rule.endpoint](**req.view_args)
  File "app.py", line 24, in ocr
    response = VisionApi().detect_text(data)
  File "/Users/varunshah1106/Documents/ocr-test/flask_server/ocr.py", line 21, in __init__
    self.credentials = GoogleCredentials.get_application_default()
  File "/Users/varunshah1106/Documents/.ocr/lib/python2.7/site-packages/oauth2client/client.py", line 1384, in get_application_default
    return GoogleCredentials._get_implicit_credentials()
  File "/Users/varunshah1106/Documents/.ocr/lib/python2.7/site-packages/oauth2client/client.py", line 1374, in _get_implicit_credentials
    raise ApplicationDefaultCredentialsError(ADC_HELP_MSG)
ApplicationDefaultCredentialsError: The Application Default Credentials are not available. They are available if running in Google Compute Engine. Otherwise, the environment variable GOOGLE_APPLICATION_CREDENTIALS must be defined pointing to a file defining the credentials. See https://developers.google.com/accounts/docs/application-default-credentials for more information.
2016-03-07 03:46:59,766 ERROR:             Exception on /ocr/ [POST] [in /Users/varunshah1106/Documents/.ocr/lib/python2.7/site-packages/flask/app.py:1423]
Traceback (most recent call last):
  File "/Users/varunshah1106/Documents/.ocr/lib/python2.7/site-packages/flask/app.py", line 1817, in wsgi_app
    response = self.full_dispatch_request()
  File "/Users/varunshah1106/Documents/.ocr/lib/python2.7/site-packages/flask/app.py", line 1477, in full_dispatch_request
    rv = self.handle_user_exception(e)
  File "/Users/varunshah1106/Documents/.ocr/lib/python2.7/site-packages/flask/app.py", line 1381, in handle_user_exception
    reraise(exc_type, exc_value, tb)
  File "/Users/varunshah1106/Documents/.ocr/lib/python2.7/site-packages/flask/app.py", line 1475, in full_dispatch_request
    rv = self.dispatch_request()
  File "/Users/varunshah1106/Documents/.ocr/lib/python2.7/site-packages/flask/app.py", line 1461, in dispatch_request
    return self.view_functions[rule.endpoint](**req.view_args)
  File "app.py", line 24, in ocr
    response = VisionApi().detect_text(data)
  File "/Users/varunshah1106/Documents/ocr-test/flask_server/ocr.py", line 21, in __init__
    self.credentials = GoogleCredentials.get_application_default()
  File "/Users/varunshah1106/Documents/.ocr/lib/python2.7/site-packages/oauth2client/client.py", line 1384, in get_application_default
    return GoogleCredentials._get_implicit_credentials()
  File "/Users/varunshah1106/Documents/.ocr/lib/python2.7/site-packages/oauth2client/client.py", line 1374, in _get_implicit_credentials
    raise ApplicationDefaultCredentialsError(ADC_HELP_MSG)
ApplicationDefaultCredentialsError: The Application Default Credentials are not available. They are available if running in Google Compute Engine. Otherwise, the environment variable GOOGLE_APPLICATION_CREDENTIALS must be defined pointing to a file defining the credentials. See https://developers.google.com/accounts/docs/application-default-credentials for more information.
2016-03-07 03:47:03,220 INFO:             errors [in app.py:57]
2016-03-07 03:47:07,649 ERROR:             Exception on /ocr/ [POST] [in /Users/varunshah1106/Documents/.ocr/lib/python2.7/site-packages/flask/app.py:1423]
Traceback (most recent call last):
  File "/Users/varunshah1106/Documents/.ocr/lib/python2.7/site-packages/flask/app.py", line 1817, in wsgi_app
    response = self.full_dispatch_request()
  File "/Users/varunshah1106/Documents/.ocr/lib/python2.7/site-packages/flask/app.py", line 1477, in full_dispatch_request
    rv = self.handle_user_exception(e)
  File "/Users/varunshah1106/Documents/.ocr/lib/python2.7/site-packages/flask/app.py", line 1381, in handle_user_exception
    reraise(exc_type, exc_value, tb)
  File "/Users/varunshah1106/Documents/.ocr/lib/python2.7/site-packages/flask/app.py", line 1475, in full_dispatch_request
    rv = self.dispatch_request()
  File "/Users/varunshah1106/Documents/.ocr/lib/python2.7/site-packages/flask/app.py", line 1461, in dispatch_request
    return self.view_functions[rule.endpoint](**req.view_args)
  File "app.py", line 24, in ocr
    response = VisionApi().detect_text(data)
  File "/Users/varunshah1106/Documents/ocr-test/flask_server/ocr.py", line 21, in __init__
    self.credentials = GoogleCredentials.get_application_default()
  File "/Users/varunshah1106/Documents/.ocr/lib/python2.7/site-packages/oauth2client/client.py", line 1384, in get_application_default
    return GoogleCredentials._get_implicit_credentials()
  File "/Users/varunshah1106/Documents/.ocr/lib/python2.7/site-packages/oauth2client/client.py", line 1374, in _get_implicit_credentials
    raise ApplicationDefaultCredentialsError(ADC_HELP_MSG)
ApplicationDefaultCredentialsError: The Application Default Credentials are not available. They are available if running in Google Compute Engine. Otherwise, the environment variable GOOGLE_APPLICATION_CREDENTIALS must be defined pointing to a file defining the credentials. See https://developers.google.com/accounts/docs/application-default-credentials for more information.
2016-03-07 03:47:36,239 INFO:             errors [in app.py:57]
2016-03-07 03:49:12,674 INFO:             errors [in app.py:57]
2016-03-07 03:50:52,468 INFO:             errors [in app.py:57]
2016-03-07 03:55:10,714 INFO:             errors [in app.py:65]
2016-03-07 03:55:22,546 ERROR:             Exception on /ocr/ [POST] [in /Users/varunshah1106/Documents/.ocr/lib/python2.7/site-packages/flask/app.py:1423]
Traceback (most recent call last):
  File "/Users/varunshah1106/Documents/.ocr/lib/python2.7/site-packages/flask/app.py", line 1817, in wsgi_app
    response = self.full_dispatch_request()
  File "/Users/varunshah1106/Documents/.ocr/lib/python2.7/site-packages/flask/app.py", line 1477, in full_dispatch_request
    rv = self.handle_user_exception(e)
  File "/Users/varunshah1106/Documents/.ocr/lib/python2.7/site-packages/flask/app.py", line 1381, in handle_user_exception
    reraise(exc_type, exc_value, tb)
  File "/Users/varunshah1106/Documents/.ocr/lib/python2.7/site-packages/flask/app.py", line 1475, in full_dispatch_request
    rv = self.dispatch_request()
  File "/Users/varunshah1106/Documents/.ocr/lib/python2.7/site-packages/flask/app.py", line 1461, in dispatch_request
    return self.view_functions[rule.endpoint](**req.view_args)
  File "app.py", line 32, in ocr
    response = VisionApi().detect_text(data)
  File "/Users/varunshah1106/Documents/ocr-test/flask_server/ocr.py", line 21, in __init__
    self.credentials = GoogleCredentials.get_application_default()
  File "/Users/varunshah1106/Documents/.ocr/lib/python2.7/site-packages/oauth2client/client.py", line 1384, in get_application_default
    return GoogleCredentials._get_implicit_credentials()
  File "/Users/varunshah1106/Documents/.ocr/lib/python2.7/site-packages/oauth2client/client.py", line 1374, in _get_implicit_credentials
    raise ApplicationDefaultCredentialsError(ADC_HELP_MSG)
ApplicationDefaultCredentialsError: The Application Default Credentials are not available. They are available if running in Google Compute Engine. Otherwise, the environment variable GOOGLE_APPLICATION_CREDENTIALS must be defined pointing to a file defining the credentials. See https://developers.google.com/accounts/docs/application-default-credentials for more information.
2016-03-07 03:55:59,529 INFO:             errors [in app.py:67]
2016-03-07 03:56:07,630 ERROR:             Exception on /ocr/ [POST] [in /Users/varunshah1106/Documents/.ocr/lib/python2.7/site-packages/flask/app.py:1423]
Traceback (most recent call last):
  File "/Users/varunshah1106/Documents/.ocr/lib/python2.7/site-packages/flask/app.py", line 1817, in wsgi_app
    response = self.full_dispatch_request()
  File "/Users/varunshah1106/Documents/.ocr/lib/python2.7/site-packages/flask/app.py", line 1477, in full_dispatch_request
    rv = self.handle_user_exception(e)
  File "/Users/varunshah1106/Documents/.ocr/lib/python2.7/site-packages/flask/app.py", line 1381, in handle_user_exception
    reraise(exc_type, exc_value, tb)
  File "/Users/varunshah1106/Documents/.ocr/lib/python2.7/site-packages/flask/app.py", line 1475, in full_dispatch_request
    rv = self.dispatch_request()
  File "/Users/varunshah1106/Documents/.ocr/lib/python2.7/site-packages/flask/app.py", line 1461, in dispatch_request
    return self.view_functions[rule.endpoint](**req.view_args)
  File "app.py", line 34, in ocr
    response = VisionApi().detect_text(data)
  File "/Users/varunshah1106/Documents/ocr-test/flask_server/ocr.py", line 21, in __init__
    self.credentials = GoogleCredentials.get_application_default()
  File "/Users/varunshah1106/Documents/.ocr/lib/python2.7/site-packages/oauth2client/client.py", line 1384, in get_application_default
    return GoogleCredentials._get_implicit_credentials()
  File "/Users/varunshah1106/Documents/.ocr/lib/python2.7/site-packages/oauth2client/client.py", line 1374, in _get_implicit_credentials
    raise ApplicationDefaultCredentialsError(ADC_HELP_MSG)
ApplicationDefaultCredentialsError: The Application Default Credentials are not available. They are available if running in Google Compute Engine. Otherwise, the environment variable GOOGLE_APPLICATION_CREDENTIALS must be defined pointing to a file defining the credentials. See https://developers.google.com/accounts/docs/application-default-credentials for more information.
2016-03-07 03:57:08,295 ERROR:             Exception on /ocr/ [POST] [in /Users/varunshah1106/Documents/.ocr/lib/python2.7/site-packages/flask/app.py:1423]
Traceback (most recent call last):
  File "/Users/varunshah1106/Documents/.ocr/lib/python2.7/site-packages/flask/app.py", line 1817, in wsgi_app
    response = self.full_dispatch_request()
  File "/Users/varunshah1106/Documents/.ocr/lib/python2.7/site-packages/flask/app.py", line 1477, in full_dispatch_request
    rv = self.handle_user_exception(e)
  File "/Users/varunshah1106/Documents/.ocr/lib/python2.7/site-packages/flask/app.py", line 1381, in handle_user_exception
    reraise(exc_type, exc_value, tb)
  File "/Users/varunshah1106/Documents/.ocr/lib/python2.7/site-packages/flask/app.py", line 1475, in full_dispatch_request
    rv = self.dispatch_request()
  File "/Users/varunshah1106/Documents/.ocr/lib/python2.7/site-packages/flask/app.py", line 1461, in dispatch_request
    return self.view_functions[rule.endpoint](**req.view_args)
  File "app.py", line 34, in ocr
    response = VisionApi().detect_text(data)
  File "/Users/varunshah1106/Documents/ocr-test/flask_server/ocr.py", line 21, in __init__
    self.credentials = GoogleCredentials.get_application_default()
  File "/Users/varunshah1106/Documents/.ocr/lib/python2.7/site-packages/oauth2client/client.py", line 1384, in get_application_default
    return GoogleCredentials._get_implicit_credentials()
  File "/Users/varunshah1106/Documents/.ocr/lib/python2.7/site-packages/oauth2client/client.py", line 1374, in _get_implicit_credentials
    raise ApplicationDefaultCredentialsError(ADC_HELP_MSG)
ApplicationDefaultCredentialsError: The Application Default Credentials are not available. They are available if running in Google Compute Engine. Otherwise, the environment variable GOOGLE_APPLICATION_CREDENTIALS must be defined pointing to a file defining the credentials. See https://developers.google.com/accounts/docs/application-default-credentials for more information.
2016-03-07 03:58:11,697 INFO:             errors [in app.py:67]
2016-03-07 03:58:26,943 ERROR:             Exception on /ocr/ [POST] [in /Users/varunshah1106/Documents/.ocr/lib/python2.7/site-packages/flask/app.py:1423]
Traceback (most recent call last):
  File "/Users/varunshah1106/Documents/.ocr/lib/python2.7/site-packages/flask/app.py", line 1817, in wsgi_app
    response = self.full_dispatch_request()
  File "/Users/varunshah1106/Documents/.ocr/lib/python2.7/site-packages/flask/app.py", line 1477, in full_dispatch_request
    rv = self.handle_user_exception(e)
  File "/Users/varunshah1106/Documents/.ocr/lib/python2.7/site-packages/flask/app.py", line 1381, in handle_user_exception
    reraise(exc_type, exc_value, tb)
  File "/Users/varunshah1106/Documents/.ocr/lib/python2.7/site-packages/flask/app.py", line 1475, in full_dispatch_request
    rv = self.dispatch_request()
  File "/Users/varunshah1106/Documents/.ocr/lib/python2.7/site-packages/flask/app.py", line 1461, in dispatch_request
    return self.view_functions[rule.endpoint](**req.view_args)
  File "app.py", line 34, in ocr
    response = VisionApi().detect_text(image.read())
  File "/Users/varunshah1106/Documents/ocr-test/flask_server/ocr.py", line 21, in __init__
    self.credentials = GoogleCredentials.get_application_default()
  File "/Users/varunshah1106/Documents/.ocr/lib/python2.7/site-packages/oauth2client/client.py", line 1384, in get_application_default
    return GoogleCredentials._get_implicit_credentials()
  File "/Users/varunshah1106/Documents/.ocr/lib/python2.7/site-packages/oauth2client/client.py", line 1374, in _get_implicit_credentials
    raise ApplicationDefaultCredentialsError(ADC_HELP_MSG)
ApplicationDefaultCredentialsError: The Application Default Credentials are not available. They are available if running in Google Compute Engine. Otherwise, the environment variable GOOGLE_APPLICATION_CREDENTIALS must be defined pointing to a file defining the credentials. See https://developers.google.com/accounts/docs/application-default-credentials for more information.
2016-03-07 03:59:12,899 INFO:             errors [in app.py:67]
2016-03-07 03:59:17,549 ERROR:             Exception on /ocr/ [POST] [in /Users/varunshah1106/Documents/.ocr/lib/python2.7/site-packages/flask/app.py:1423]
Traceback (most recent call last):
  File "/Users/varunshah1106/Documents/.ocr/lib/python2.7/site-packages/flask/app.py", line 1817, in wsgi_app
    response = self.full_dispatch_request()
  File "/Users/varunshah1106/Documents/.ocr/lib/python2.7/site-packages/flask/app.py", line 1477, in full_dispatch_request
    rv = self.handle_user_exception(e)
  File "/Users/varunshah1106/Documents/.ocr/lib/python2.7/site-packages/flask/app.py", line 1381, in handle_user_exception
    reraise(exc_type, exc_value, tb)
  File "/Users/varunshah1106/Documents/.ocr/lib/python2.7/site-packages/flask/app.py", line 1475, in full_dispatch_request
    rv = self.dispatch_request()
  File "/Users/varunshah1106/Documents/.ocr/lib/python2.7/site-packages/flask/app.py", line 1461, in dispatch_request
    return self.view_functions[rule.endpoint](**req.view_args)
  File "app.py", line 34, in ocr
    response = VisionApi().detect_text(image.read())
  File "/Users/varunshah1106/Documents/ocr-test/flask_server/ocr.py", line 21, in __init__
    self.credentials = GoogleCredentials.get_application_default()
  File "/Users/varunshah1106/Documents/.ocr/lib/python2.7/site-packages/oauth2client/client.py", line 1384, in get_application_default
    return GoogleCredentials._get_implicit_credentials()
  File "/Users/varunshah1106/Documents/.ocr/lib/python2.7/site-packages/oauth2client/client.py", line 1374, in _get_implicit_credentials
    raise ApplicationDefaultCredentialsError(ADC_HELP_MSG)
ApplicationDefaultCredentialsError: The Application Default Credentials are not available. They are available if running in Google Compute Engine. Otherwise, the environment variable GOOGLE_APPLICATION_CREDENTIALS must be defined pointing to a file defining the credentials. See https://developers.google.com/accounts/docs/application-default-credentials for more information.
2016-03-07 04:00:12,395 INFO:             errors [in app.py:67]
2016-03-07 04:00:16,488 ERROR:             Exception on /ocr/ [POST] [in /Users/varunshah1106/Documents/.ocr/lib/python2.7/site-packages/flask/app.py:1423]
Traceback (most recent call last):
  File "/Users/varunshah1106/Documents/.ocr/lib/python2.7/site-packages/flask/app.py", line 1817, in wsgi_app
    response = self.full_dispatch_request()
  File "/Users/varunshah1106/Documents/.ocr/lib/python2.7/site-packages/flask/app.py", line 1477, in full_dispatch_request
    rv = self.handle_user_exception(e)
  File "/Users/varunshah1106/Documents/.ocr/lib/python2.7/site-packages/flask/app.py", line 1381, in handle_user_exception
    reraise(exc_type, exc_value, tb)
  File "/Users/varunshah1106/Documents/.ocr/lib/python2.7/site-packages/flask/app.py", line 1475, in full_dispatch_request
    rv = self.dispatch_request()
  File "/Users/varunshah1106/Documents/.ocr/lib/python2.7/site-packages/flask/app.py", line 1461, in dispatch_request
    return self.view_functions[rule.endpoint](**req.view_args)
  File "app.py", line 34, in ocr
    response = VisionApi().detect_text(image.read())
  File "/Users/varunshah1106/Documents/ocr-test/flask_server/ocr.py", line 21, in __init__
    self.credentials = GoogleCredentials.get_application_default()
  File "/Users/varunshah1106/Documents/.ocr/lib/python2.7/site-packages/oauth2client/client.py", line 1384, in get_application_default
    return GoogleCredentials._get_implicit_credentials()
  File "/Users/varunshah1106/Documents/.ocr/lib/python2.7/site-packages/oauth2client/client.py", line 1374, in _get_implicit_credentials
    raise ApplicationDefaultCredentialsError(ADC_HELP_MSG)
ApplicationDefaultCredentialsError: The Application Default Credentials are not available. They are available if running in Google Compute Engine. Otherwise, the environment variable GOOGLE_APPLICATION_CREDENTIALS must be defined pointing to a file defining the credentials. See https://developers.google.com/accounts/docs/application-default-credentials for more information.
2016-03-07 04:04:41,959 INFO:             errors [in app.py:67]
2016-03-07 04:04:48,901 ERROR:             Exception on /ocr/ [POST] [in /Users/varunshah1106/Documents/.ocr/lib/python2.7/site-packages/flask/app.py:1423]
Traceback (most recent call last):
  File "/Users/varunshah1106/Documents/.ocr/lib/python2.7/site-packages/flask/app.py", line 1817, in wsgi_app
    response = self.full_dispatch_request()
  File "/Users/varunshah1106/Documents/.ocr/lib/python2.7/site-packages/flask/app.py", line 1477, in full_dispatch_request
    rv = self.handle_user_exception(e)
  File "/Users/varunshah1106/Documents/.ocr/lib/python2.7/site-packages/flask/app.py", line 1381, in handle_user_exception
    reraise(exc_type, exc_value, tb)
  File "/Users/varunshah1106/Documents/.ocr/lib/python2.7/site-packages/flask/app.py", line 1475, in full_dispatch_request
    rv = self.dispatch_request()
  File "/Users/varunshah1106/Documents/.ocr/lib/python2.7/site-packages/flask/app.py", line 1461, in dispatch_request
    return self.view_functions[rule.endpoint](**req.view_args)
  File "app.py", line 34, in ocr
    response = VisionApi().detect_text(image.read())
  File "/Users/varunshah1106/Documents/ocr-test/flask_server/ocr.py", line 44, in detect_text
    'maxResults': max_result,
NameError: global name 'max_result' is not defined
2016-03-07 04:05:21,374 INFO:             errors [in app.py:66]
2016-03-07 04:05:47,327 INFO:             errors [in app.py:66]
2016-03-07 04:06:03,443 INFO:             errors [in app.py:66]
2016-03-07 04:10:15,912 INFO:             errors [in app.py:61]
2016-03-07 04:10:49,099 INFO:             errors [in app.py:61]
2016-03-07 04:19:06,083 INFO:             errors [in app.py:61]
2016-03-07 04:19:29,128 INFO:             errors [in app.py:61]
2016-03-07 04:22:31,482 INFO:             errors [in app.py:61]
2016-03-07 04:24:35,673 INFO:             errors [in app.py:61]
2016-03-07 04:27:33,058 INFO:             errors [in app.py:62]
2016-03-07 04:28:41,964 INFO:             errors [in app.py:62]
2016-03-07 04:29:14,377 INFO:             errors [in app.py:63]
2016-03-07 04:29:19,678 ERROR:             Exception on /ocr/ [POST] [in /Users/varunshah1106/Documents/.ocr/lib/python2.7/site-packages/flask/app.py:1423]
Traceback (most recent call last):
  File "/Users/varunshah1106/Documents/.ocr/lib/python2.7/site-packages/flask/app.py", line 1817, in wsgi_app
    response = self.full_dispatch_request()
  File "/Users/varunshah1106/Documents/.ocr/lib/python2.7/site-packages/flask/app.py", line 1477, in full_dispatch_request
    rv = self.handle_user_exception(e)
  File "/Users/varunshah1106/Documents/.ocr/lib/python2.7/site-packages/flask/app.py", line 1381, in handle_user_exception
    reraise(exc_type, exc_value, tb)
  File "/Users/varunshah1106/Documents/.ocr/lib/python2.7/site-packages/flask/app.py", line 1475, in full_dispatch_request
    rv = self.dispatch_request()
  File "/Users/varunshah1106/Documents/.ocr/lib/python2.7/site-packages/flask/app.py", line 1461, in dispatch_request
    return self.view_functions[rule.endpoint](**req.view_args)
  File "app.py", line 29, in ocr
    response = json.loads(VisionApi().detect_text(image.read()))
  File "/System/Library/Frameworks/Python.framework/Versions/2.7/lib/python2.7/json/__init__.py", line 338, in loads
    return _default_decoder.decode(s)
  File "/System/Library/Frameworks/Python.framework/Versions/2.7/lib/python2.7/json/decoder.py", line 366, in decode
    obj, end = self.raw_decode(s, idx=_w(s, 0).end())
TypeError: expected string or buffer
2016-03-07 04:29:51,376 INFO:             errors [in app.py:64]
2016-03-07 04:30:21,125 INFO:             errors [in app.py:64]
2016-03-07 04:30:26,343 ERROR:             Exception on /ocr/ [POST] [in /Users/varunshah1106/Documents/.ocr/lib/python2.7/site-packages/flask/app.py:1423]
Traceback (most recent call last):
  File "/Users/varunshah1106/Documents/.ocr/lib/python2.7/site-packages/flask/app.py", line 1817, in wsgi_app
    response = self.full_dispatch_request()
  File "/Users/varunshah1106/Documents/.ocr/lib/python2.7/site-packages/flask/app.py", line 1477, in full_dispatch_request
    rv = self.handle_user_exception(e)
  File "/Users/varunshah1106/Documents/.ocr/lib/python2.7/site-packages/flask/app.py", line 1381, in handle_user_exception
    reraise(exc_type, exc_value, tb)
  File "/Users/varunshah1106/Documents/.ocr/lib/python2.7/site-packages/flask/app.py", line 1475, in full_dispatch_request
    rv = self.dispatch_request()
  File "/Users/varunshah1106/Documents/.ocr/lib/python2.7/site-packages/flask/app.py", line 1461, in dispatch_request
    return self.view_functions[rule.endpoint](**req.view_args)
  File "app.py", line 29, in ocr
    response = json.loads(VisionApi().detect_text(image.read())[0])
  File "/System/Library/Frameworks/Python.framework/Versions/2.7/lib/python2.7/json/__init__.py", line 338, in loads
    return _default_decoder.decode(s)
  File "/System/Library/Frameworks/Python.framework/Versions/2.7/lib/python2.7/json/decoder.py", line 366, in decode
    obj, end = self.raw_decode(s, idx=_w(s, 0).end())
TypeError: expected string or buffer
2016-03-07 04:30:56,495 INFO:             errors [in app.py:66]
2016-03-07 04:31:00,750 ERROR:             Exception on /ocr/ [POST] [in /Users/varunshah1106/Documents/.ocr/lib/python2.7/site-packages/flask/app.py:1423]
Traceback (most recent call last):
  File "/Users/varunshah1106/Documents/.ocr/lib/python2.7/site-packages/flask/app.py", line 1817, in wsgi_app
    response = self.full_dispatch_request()
  File "/Users/varunshah1106/Documents/.ocr/lib/python2.7/site-packages/flask/app.py", line 1477, in full_dispatch_request
    rv = self.handle_user_exception(e)
  File "/Users/varunshah1106/Documents/.ocr/lib/python2.7/site-packages/flask/app.py", line 1381, in handle_user_exception
    reraise(exc_type, exc_value, tb)
  File "/Users/varunshah1106/Documents/.ocr/lib/python2.7/site-packages/flask/app.py", line 1475, in full_dispatch_request
    rv = self.dispatch_request()
  File "/Users/varunshah1106/Documents/.ocr/lib/python2.7/site-packages/flask/app.py", line 1461, in dispatch_request
    return self.view_functions[rule.endpoint](**req.view_args)
  File "app.py", line 31, in ocr
    response = json.loads(response[0])
  File "/System/Library/Frameworks/Python.framework/Versions/2.7/lib/python2.7/json/__init__.py", line 338, in loads
    return _default_decoder.decode(s)
  File "/System/Library/Frameworks/Python.framework/Versions/2.7/lib/python2.7/json/decoder.py", line 366, in decode
    obj, end = self.raw_decode(s, idx=_w(s, 0).end())
TypeError: expected string or buffer
2016-03-07 04:31:37,872 INFO:             errors [in app.py:64]
2016-03-07 04:31:41,638 ERROR:             Exception on /ocr/ [POST] [in /Users/varunshah1106/Documents/.ocr/lib/python2.7/site-packages/flask/app.py:1423]
Traceback (most recent call last):
  File "/Users/varunshah1106/Documents/.ocr/lib/python2.7/site-packages/flask/app.py", line 1817, in wsgi_app
    response = self.full_dispatch_request()
  File "/Users/varunshah1106/Documents/.ocr/lib/python2.7/site-packages/flask/app.py", line 1477, in full_dispatch_request
    rv = self.handle_user_exception(e)
  File "/Users/varunshah1106/Documents/.ocr/lib/python2.7/site-packages/flask/app.py", line 1381, in handle_user_exception
    reraise(exc_type, exc_value, tb)
  File "/Users/varunshah1106/Documents/.ocr/lib/python2.7/site-packages/flask/app.py", line 1475, in full_dispatch_request
    rv = self.dispatch_request()
  File "/Users/varunshah1106/Documents/.ocr/lib/python2.7/site-packages/flask/app.py", line 1461, in dispatch_request
    return self.view_functions[rule.endpoint](**req.view_args)
  File "app.py", line 31, in ocr
    print response[0]['textAnnotations'][0]['description'][0]
KeyError: 0
2016-03-07 04:32:28,649 INFO:             errors [in app.py:64]
2016-03-07 04:32:42,947 ERROR:             Exception on /ocr/ [POST] [in /Users/varunshah1106/Documents/.ocr/lib/python2.7/site-packages/flask/app.py:1423]
Traceback (most recent call last):
  File "/Users/varunshah1106/Documents/.ocr/lib/python2.7/site-packages/flask/app.py", line 1817, in wsgi_app
    response = self.full_dispatch_request()
  File "/Users/varunshah1106/Documents/.ocr/lib/python2.7/site-packages/flask/app.py", line 1477, in full_dispatch_request
    rv = self.handle_user_exception(e)
  File "/Users/varunshah1106/Documents/.ocr/lib/python2.7/site-packages/flask/app.py", line 1381, in handle_user_exception
    reraise(exc_type, exc_value, tb)
  File "/Users/varunshah1106/Documents/.ocr/lib/python2.7/site-packages/flask/app.py", line 1475, in full_dispatch_request
    rv = self.dispatch_request()
  File "/Users/varunshah1106/Documents/.ocr/lib/python2.7/site-packages/flask/app.py", line 1461, in dispatch_request
    return self.view_functions[rule.endpoint](**req.view_args)
  File "app.py", line 31, in ocr
    print response[0]['textAnnotations'][0]['description'][0]
KeyError: 0
2016-03-07 04:38:24,650 INFO:             errors [in app.py:64]
2016-03-07 04:38:35,305 ERROR:             Exception on /ocr/ [POST] [in /Users/varunshah1106/Documents/.ocr/lib/python2.7/site-packages/flask/app.py:1423]
Traceback (most recent call last):
  File "/Users/varunshah1106/Documents/.ocr/lib/python2.7/site-packages/flask/app.py", line 1817, in wsgi_app
    response = self.full_dispatch_request()
  File "/Users/varunshah1106/Documents/.ocr/lib/python2.7/site-packages/flask/app.py", line 1477, in full_dispatch_request
    rv = self.handle_user_exception(e)
  File "/Users/varunshah1106/Documents/.ocr/lib/python2.7/site-packages/flask/app.py", line 1381, in handle_user_exception
    reraise(exc_type, exc_value, tb)
  File "/Users/varunshah1106/Documents/.ocr/lib/python2.7/site-packages/flask/app.py", line 1475, in full_dispatch_request
    rv = self.dispatch_request()
  File "/Users/varunshah1106/Documents/.ocr/lib/python2.7/site-packages/flask/app.py", line 1461, in dispatch_request
    return self.view_functions[rule.endpoint](**req.view_args)
  File "app.py", line 31, in ocr
    print response[0]['textAnnotations'][0]['description'][0]
KeyError: 0
2016-03-07 04:39:18,061 INFO:             errors [in app.py:64]
2016-03-07 04:52:04,999 INFO:             errors [in app.py:66]
2016-03-07 04:52:12,885 ERROR:             Exception on /ocr/ [POST] [in /Users/varunshah1106/Documents/.ocr/lib/python2.7/site-packages/flask/app.py:1423]
Traceback (most recent call last):
  File "/Users/varunshah1106/Documents/.ocr/lib/python2.7/site-packages/flask/app.py", line 1817, in wsgi_app
    response = self.full_dispatch_request()
  File "/Users/varunshah1106/Documents/.ocr/lib/python2.7/site-packages/flask/app.py", line 1477, in full_dispatch_request
    rv = self.handle_user_exception(e)
  File "/Users/varunshah1106/Documents/.ocr/lib/python2.7/site-packages/flask/app.py", line 1381, in handle_user_exception
    reraise(exc_type, exc_value, tb)
  File "/Users/varunshah1106/Documents/.ocr/lib/python2.7/site-packages/flask/app.py", line 1475, in full_dispatch_request
    rv = self.dispatch_request()
  File "/Users/varunshah1106/Documents/.ocr/lib/python2.7/site-packages/flask/app.py", line 1461, in dispatch_request
    return self.view_functions[rule.endpoint](**req.view_args)
  File "app.py", line 44, in ocr
    print pytesseract.image_to_string(image)
  File "/Users/varunshah1106/Documents/.ocr/lib/python2.7/site-packages/pytesseract/pytesseract.py", line 142, in image_to_string
    config=config)
  File "/Users/varunshah1106/Documents/.ocr/lib/python2.7/site-packages/pytesseract/pytesseract.py", line 75, in run_tesseract
    stderr=subprocess.PIPE)
  File "/System/Library/Frameworks/Python.framework/Versions/2.7/lib/python2.7/subprocess.py", line 710, in __init__
    errread, errwrite)
  File "/System/Library/Frameworks/Python.framework/Versions/2.7/lib/python2.7/subprocess.py", line 1335, in _execute_child
    raise child_exception
OSError: [Errno 2] No such file or directory
2016-03-07 04:53:20,526 INFO:             errors [in app.py:66]
2016-03-07 04:53:24,302 ERROR:             Exception on /ocr/ [POST] [in /Users/varunshah1106/Documents/.ocr/lib/python2.7/site-packages/flask/app.py:1423]
Traceback (most recent call last):
  File "/Users/varunshah1106/Documents/.ocr/lib/python2.7/site-packages/flask/app.py", line 1817, in wsgi_app
    response = self.full_dispatch_request()
  File "/Users/varunshah1106/Documents/.ocr/lib/python2.7/site-packages/flask/app.py", line 1477, in full_dispatch_request
    rv = self.handle_user_exception(e)
  File "/Users/varunshah1106/Documents/.ocr/lib/python2.7/site-packages/flask/app.py", line 1381, in handle_user_exception
    reraise(exc_type, exc_value, tb)
  File "/Users/varunshah1106/Documents/.ocr/lib/python2.7/site-packages/flask/app.py", line 1475, in full_dispatch_request
    rv = self.dispatch_request()
  File "/Users/varunshah1106/Documents/.ocr/lib/python2.7/site-packages/flask/app.py", line 1461, in dispatch_request
    return self.view_functions[rule.endpoint](**req.view_args)
  File "app.py", line 44, in ocr
    print pytesseract.image_to_string(image.read())
  File "/Users/varunshah1106/Documents/.ocr/lib/python2.7/site-packages/pytesseract/pytesseract.py", line 137, in image_to_string
    image.save(input_file_name)
AttributeError: 'str' object has no attribute 'save'
2016-03-07 04:53:49,917 INFO:             errors [in app.py:66]
2016-03-07 04:53:53,624 ERROR:             Exception on /ocr/ [POST] [in /Users/varunshah1106/Documents/.ocr/lib/python2.7/site-packages/flask/app.py:1423]
Traceback (most recent call last):
  File "/Users/varunshah1106/Documents/.ocr/lib/python2.7/site-packages/flask/app.py", line 1817, in wsgi_app
    response = self.full_dispatch_request()
  File "/Users/varunshah1106/Documents/.ocr/lib/python2.7/site-packages/flask/app.py", line 1477, in full_dispatch_request
    rv = self.handle_user_exception(e)
  File "/Users/varunshah1106/Documents/.ocr/lib/python2.7/site-packages/flask/app.py", line 1381, in handle_user_exception
    reraise(exc_type, exc_value, tb)
  File "/Users/varunshah1106/Documents/.ocr/lib/python2.7/site-packages/flask/app.py", line 1475, in full_dispatch_request
    rv = self.dispatch_request()
  File "/Users/varunshah1106/Documents/.ocr/lib/python2.7/site-packages/flask/app.py", line 1461, in dispatch_request
    return self.view_functions[rule.endpoint](**req.view_args)
  File "app.py", line 44, in ocr
    pytesseract.image_to_string(image.read())
  File "/Users/varunshah1106/Documents/.ocr/lib/python2.7/site-packages/pytesseract/pytesseract.py", line 137, in image_to_string
    image.save(input_file_name)
AttributeError: 'str' object has no attribute 'save'
2016-03-07 04:55:53,289 INFO:             errors [in app.py:66]
2016-03-07 04:55:57,578 ERROR:             Exception on /ocr/ [POST] [in /Users/varunshah1106/Documents/.ocr/lib/python2.7/site-packages/flask/app.py:1423]
Traceback (most recent call last):
  File "/Users/varunshah1106/Documents/.ocr/lib/python2.7/site-packages/flask/app.py", line 1817, in wsgi_app
    response = self.full_dispatch_request()
  File "/Users/varunshah1106/Documents/.ocr/lib/python2.7/site-packages/flask/app.py", line 1477, in full_dispatch_request
    rv = self.handle_user_exception(e)
  File "/Users/varunshah1106/Documents/.ocr/lib/python2.7/site-packages/flask/app.py", line 1381, in handle_user_exception
    reraise(exc_type, exc_value, tb)
  File "/Users/varunshah1106/Documents/.ocr/lib/python2.7/site-packages/flask/app.py", line 1475, in full_dispatch_request
    rv = self.dispatch_request()
  File "/Users/varunshah1106/Documents/.ocr/lib/python2.7/site-packages/flask/app.py", line 1461, in dispatch_request
    return self.view_functions[rule.endpoint](**req.view_args)
  File "app.py", line 44, in ocr
    pytesseract.image_to_string(image.open())
  File "/Users/varunshah1106/Documents/.ocr/lib/python2.7/site-packages/werkzeug/datastructures.py", line 2595, in __getattr__
    return getattr(self.stream, name)
AttributeError: '_io.BytesIO' object has no attribute 'open'
